Workbook

Sheet Guião
B2: GUIÃO DE PREENCHIMENTO
B3: O processo de Avaliação de Desempenho foi estruturado em etapas, com o objetivo de garantir maior foco em cada momento, promover discussões mais qualificadas e assegurar um melhor acompanhamento ao longo do ano. Mais do que um preenchimento formal, este processo deve ser encarado como um momento de diálogo, alinhamento e desenvolvimento entre colaborador e gestor.
B5: Visão geral do processo
B6: Na primeira etapa, o foco está exclusivamente na definição dos objetivos e KPIs para 2026 (Secção 4)
B7: · Colaborador propõe os objetivos e KPIs
B8: · Gestor revisa, ajusta e valida em conjunto os KPIS
B9: · Realização de reunião individual (1:1) para alinhamento
B10: As demais secções do ficheiro serão preenchidas ao final do ciclo avaliativo
B12: Como preencher o ficheiro
B13: Secção 1 – Identificação do Colaborador
B14: Responsável: Gestor
B15: · Confirmar os dados do colaborador
... B78: Em caso de dúvidas, entre em contato com a área de People.

Sheet ADC
B2: Avaliação de Desempenho e Competências
B3: 2026 | EM3: G2
B5: A AVALIAÇÃO DE DESEMPENHO
B6: A Avaliação de Desempenho da Tlantic tem como objetivo promover uma visão equilibrada da atuação profissional, considerando resultados alcançados e competências comportamentais, alinhadas aos nossos valores. Este processo procura fortalecer o alinhamento de expectativas, apoiar conversas de feedback e contribuir para o desenvolvimento contínuo e a evolução profissional. Conduza a avaliação com transparência, responsabilidade e foco no crescimento.
B11: 1. IDENTIFICAÇÃO DO COLABORADOR
C13: Nome Colaborador | F13: Nº Colaborador | I13: Data da avaliação | L13: Geografia | N13: Ano de avaliação
C16: Função | F16: Nível Hierárquico | I16: Avaliador | L16: Equipa | N16: Data de admissão
B20: 2. O CICLO ANTERIOR: REFLEXÃO
C22: Este espaço destina-se a expor a reflexão sobre o ciclo anterior, incluindo principais entregas, sucessos e pontos de melhoria, na perspetiva do colaborador e do gestor.
D24: Principais entregas e resultados do período | G24: Principais desafios enfrentados | L24: Pontos a desenvolver
C25: COLABORADOR
C26: GESTOR
B29: 3. COMPETENCIAS COMPORTAMENTAIS
C31: Avaliação das competências comportamentais alinhadas com os valores da Tlantic.
C33: OS NOSSOS VALORES | E33: COMPETENCIA | G33: DESCRIÇÃO | N33: AVALIAÇÃO
C34: Agilidade Criativa | E34: Inovação e adaptação | G34: =IFERROR(VLOOKUP($F$17&$C34,MATRIZ!$A:$E,5,0),"Preencher o campo 'Nível Hierárquico'") -> Preencher o campo 'Nível Hierárquico'
C35: Espirito de Equipa | E35: Colaboração | G35: =IFERROR(VLOOKUP($F$17&$C35,MATRIZ!$A:$E,5,0),"Preencher o campo 'Nível Hierárquico'") -> Preencher o campo 'Nível Hierárquico'
C36: Flexibilidade | E36: Adaptabilidade | G36: =IFERROR(VLOOKUP($F$17&$C36,MATRIZ!$A:$E,5,0),"Preencher o campo 'Nível Hierárquico'") -> Preencher o campo 'Nível Hierárquico'
C37: Integridade e Respeito | E37: Ética profissional | G37: =IFERROR(VLOOKUP($F$17&$C37,MATRIZ!$A:$E,5,0),"Preencher o campo 'Nível Hierárquico'") -> Preencher o campo 'Nível Hierárquico'
C38: Valorização das Pessoas | E38: Desenvolvimento | G38: =IFERROR(VLOOKUP($F$17&$C38,MATRIZ!$A:$E,5,0),"Preencher o campo 'Nível Hierárquico'") -> Preencher o campo 'Nível Hierárquico'
B41: =+"4. OBJETIVOS e KPIs "&B3&" : DEFINIÇÃO & RESULTADOS" -> 4. OBJETIVOS e KPIs 2026 : DEFINIÇÃO & RESULTADOS
C43: Análise e apuramento dos KPIs do ciclo, com base em dados e resultados obtidos.
C45: INDIVIDUAL | E45: Un. | F45: Peso | G45: Objectivo | J45: Resultado | K45: % Realização | L45: % Ajustado | M45: Avaliação | N45: Comentários
G46: min | H46: obj | I46: max
C47: Quantitativo | K47: =IFERROR(J47/H47,0) -> 0 | L47: =IFERROR(IF(J47<G47,0,IF(J47<=H47,((20%*(J47-G47))/(H47-G47))+80%,IF(J47>I47,1.2,((20%*(J47-H47))/(I47-H47))+100%))),0) -> 0 | M47: =+L47*F47 -> 0
K48: =IFERROR(J48/H48,0) -> 0 | L48: =IFERROR(IF(J48<G48,0,IF(J48<=H48,((20%*(J48-G48))/(H48-G48))+80%,IF(J48>I48,1.2,((20%*(J48-H48))/(I48-H48))+100%))),0) -> 0 | M48: =+L48*F48 -> 0
K49: =IFERROR(J49/H49,0) -> 0 | L49: =IFERROR(IF(J49<G49,0,IF(J49<=H49,((20%*(J49-G49))/(H49-G49))+80%,IF(J49>I49,1.2,((20%*(J49-H49))/(I49-H49))+100%))),0) -> 0 | M49: =+L49*F49 -> 0
K50: =IFERROR(J50/H50,0) -> 0 | L50: =IFERROR(IF(J50<G50,0,IF(J50<=H50,((20%*(J50-G50))/(H50-G50))+80%,IF(J50>I50,1.2,((20%*(J50-H50))/(I50-H50))+100%))),0) -> 0 | M50: =+L50*F50 -> 0
C51: Qualitativo | K51: =IFERROR(J51/H51,0) -> 0 | L51: =IFERROR(IF(J51<G51,0,IF(J51<=H51,((20%*(J51-G51))/(H51-G51))+80%,IF(J51>I51,1.2,((20%*(J51-H51))/(I51-H51))+100%))),0) -> 0 | M51: =+L51*F51 -> 0
K52: =IFERROR(J52/H52,0) -> 0 | L52: =IFERROR(IF(J52<G52,0,IF(J52<=H52,((20%*(J52-G52))/(H52-G52))+80%,IF(J52>I52,1.2,((20%*(J52-H52))/(I52-H52))+100%))),0) -> 0 | M52: =+L52*F52 -> 0
K53: =IFERROR(J53/H53,0) -> 0 | L53: =IFERROR(IF(J53<G53,0,IF(J53<=H53,((20%*(J53-G53))/(H53-G53))+80%,IF(J53>I53,1.2,((20%*(J53-H53))/(I53-H53))+100%))),0) -> 0 | M53: =+L53*F53 -> 0
K54: =IFERROR(J54/H54,0) -> 0 | L54: =IFERROR(IF(J54<G54,0,IF(J54<=H54,((20%*(J54-G54))/(H54-G54))+80%,IF(J54>I54,1.2,((20%*(J54-H54))/(I54-H54))+100%))),0) -> 0 | M54: =+L54*F54 -> 0
F55: =SUM(F47:F54) -> 0 | I55: RESULTADO | M55: =SUM(M47:M54) -> 0
A58: 5. Necessidades de Desenvolvimento e Formação | B58: 5. REFLEXÃO SOBRE A LIDERANÇA
C60: Este espaço destina-se a recolher a tua perceção sobre a forma de acompanhamento e colaboração no dia a dia, com foco na melhoria contínua.
C62: As prioridades e expectativas do meu trabalho são claras.
C63: Sinto que tenho o apoio necessário para desempenhar bem as minhas funções.
C64: Tenho autonomia adequada para executar o meu trabalho.
C65: Recebo feedback útil para melhorar o meu desempenho.
C66: O que poderia ser feito para melhorar o teu dia a dia ou a colaboração com a liderança?
...

Sheet MATRIZ
A1: Controle | B1: Valor | C1: Competência | D1: Nível | E1: Comportamento Esperado
A2: =Tabela1[[#This Row],[Nível]]&Tabela1[[#This Row],[Valor]] -> TraineeAgilidade Criativa | B2: Agilidade Criativa | C2: Inovação e adaptação | D2: Trainee | E2: Aprende rapidamente, adapta-se a novas rotinas e executa atividades com orientação constante, demonstrando curiosidade e abertura a novas ideias.
A3: =Tabela1[[#This Row],[Nível]]&Tabela1[[#This Row],[Valor]] -> JuniorAgilidade Criativa | B3: Agilidade Criativa | C3: Inovação e adaptação | D3: Junior | E3: Executa atividades com autonomia inicial, adapta-se a mudanças e aplica aprendizados no dia a dia.
A4: =Tabela1[[#This Row],[Nível]]&Tabela1[[#This Row],[Valor]] -> AssociateAgilidade Criativa | B4: Agilidade Criativa | C4: Inovação e adaptação | D4: Associate | E4: Identifica melhorias no trabalho, adapta-se com autonomia e contribui com soluções práticas.
A5: =Tabela1[[#This Row],[Nível]]&Tabela1[[#This Row],[Valor]] -> SeniorAgilidade Criativa | B5: Agilidade Criativa | C5: Inovação e adaptação | D5: Senior | E5: Propõe soluções inovadoras, antecipa riscos e adapta processos com pensamento crítico.
A6: =Tabela1[[#This Row],[Nível]]&Tabela1[[#This Row],[Valor]] -> LeadAgilidade Criativa | B6: Agilidade Criativa | C6: Inovação e adaptação | D6: Lead | E6: Estimula inovação no time, conduz mudanças e desenvolve pensamento crítico coletivo.
A7: =Tabela1[[#This Row],[Nível]]&Tabela1[[#This Row],[Valor]] -> PrincipalAgilidade Criativa | B7: Agilidade Criativa | C7: Inovação e adaptação | D7: Principal | E7: Influencia decisões estratégicas e lidera transformações organizacionais com visão inovadora.
A8: =Tabela1[[#This Row],[Nível]]&Tabela1[[#This Row],[Valor]] -> TraineeEspirito de equipa | B8: Espirito de equipa | C8: Colaboração, comunicação e trabalho em equipa | D8: Trainee | E8: Colabora com a equipa, comunica-se com respeito e segue orientações.
A9: =Tabela1[[#This Row],[Nível]]&Tabela1[[#This Row],[Valor]] -> JuniorEspirito de equipa | B9: Espirito de equipa | C9: Colaboração, comunicação e trabalho em equipa | D9: Junior | E9: Colabora de forma consistente e mantém comunicação clara no dia a dia
A10: =Tabela1[[#This Row],[Nível]]&Tabela1[[#This Row],[Valor]] -> AssociateEspirito de equipa | B10: Espirito de equipa | C10: Colaboração, comunicação e trabalho em equipa | D10: Associate | E10: Colabora ativamente, compartilha conhecimento e apoia colegas.
A11: =Tabela1[[#This Row],[Nível]]&Tabela1[[#This Row],[Valor]] -> SeniorEspirito de equipa | B11: Espirito de equipa | C11: Colaboração, comunicação e trabalho em equipa | D11: Senior | E11: Atua como referência, promove cooperação e alinhamento entre pares.
A12: =Tabela1[[#This Row],[Nível]]&Tabela1[[#This Row],[Valor]] -> LeadEspirito de equipa | B12: Espirito de equipa | C12: Colaboração, comunicação e trabalho em equipa | D12: Lead | E12: Desenvolve o time, facilita diálogos e fortalece a confiança da equipa
A13: =Tabela1[[#This Row],[Nível]]&Tabela1[[#This Row],[Valor]] -> PrincipalEspirito de equipa | B13: Espirito de equipa | C13: Colaboração, comunicação e trabalho em equipa | D13: Principal | E13: Cria ambientes colaborativos e influencia a cultura de trabalho em equipa.
... A31: =Tabela1[[#This Row],[Nível]]&Tabela1[[#This Row],[Valor]] -> PrincipalValorização das Pessoas | B31: Valorização das Pessoas | C31: Desenvolvimento, aprendizado e apoio ao crescimento | D31: Principal | E31: Promove cultura de desenvolvimento e crescimento sustentável.

Sheet EXEMPLOS KPIs
B5: INDIVIDUAL | D5: Un. | E5: Peso | F5: Objectivo
F6: min | G6: obj | H6: max
B7: Quantitativo | C7: Relatórios mensais: garantir que todos os relatórios estão prontos até ao dia x de cada mês | D7: # | E7: 0.1 | F7: 30 | G7: 34 | H7: 36
C8: Cumprimento dos SLAs dos Clientes XX nos registos encerrados | D8: % | E8: 0.2 | F8: 0.95 | G8: 0.98 | H8: 1
C9: Gestão das sprints de desenvolvimento (planeamento, controlo e fecho) - nº entregas ontime/ nº total entregas | D9: % | E9: 0.4 | F9: 0.6 | G9: 0.8 | H9: 1
C10: Número projetos implementados de integração "plug-and-play" | D10: # | E10: 0.3 | F10: 2 | G10: 3 | H10: 5
C11: Número de sprints entregues no produto XXX | D11: # | E11: 0.2 | F11: 15 | G11: 16 | H11: 18
C12: 1- % de bugs encontrados pelo QA antes de produção ponderados por severidade | D12: % | E12: 0.15 | F12: 0.92 | G12: 0.95 | H12: 1
C13: Desenvolvimento das entregas do PL/SQL de acordo com o planeamento das sprints / total de entregas | D13: % | E13: 0.3 | F13: 0.7 | G13: 0.8 | H13: 1.2
C14: Nº Desenvolimentos entregues sem bugs críticos (identificados em QA) / Nº Total Desenvolimentos entregues | D14: % | E14: 0.15 | F14: 0.92 | G14: 0.95 | H14: 1
C15: Índice de satisfação do cliente - avaliação de entrega de projetos | D15: # | E15: 0.2 | F15: 4.9 | G15: 5.2 | H15: 6
C16: Nº Desenvolimentos entregues sem bugs críticos (identificados em Prod) / Nº Total Desenvolimentos entregues | D16: % | E16: 0.3 | F16: 0.97 | G16: 0.99 | H16: 1
B17: Qualitativo | C17: Ampliar o nível de autonomia na execução das atividades, assumindo maior responsabilidade pelas entregas e decisões técnicas compatíveis com a função | D17: % | E17: 0.05 | F17: 0.8 | G17: 0.9 | H17: 1
C18: Adquirir e reforçar conhecimentos técnicos relacionados aos temas e tecnologias trabalhados na função. | D18: % | E18: 0.05 | F18: 0.7 | G18: 0.95 | H18: 1
C19: Participar de reuniões técnicas, contribuindo com sugestões, apontamentos críticos e colaborando na tomada de decisões técnicas. | D19: % | E19: 0.1 | F19: 0.8 | G19: 0.9 | H19: 1
C20: Autonomia Técnica e Desenvolvimento da Equipa - Desenvolvimento de tarefas end-to-end; Suporte a colegas quando necessário | D20: % | E20: 0.25 | F20: 0.8 | G20: 0.9 | H20: 1
C21: Melhoria de Produto e Processos - Sugestões e implementações de melhorias locais | D21: % | E21: 0.1 | F21: 0.6 | G21: 0.9 | H21: 1
C22: Fortalecer a cooperação com a equipa e áreas parceiras, contribuindo para o trabalho coletivo e compartilhamento de conhecimento. | D22: % | E22: 0.1 | F22: 0.8 | G22: 0.9 | H22: 1
C23: Contribuir com sugestões de melhoria para produtos, processos ou práticas da equipa, promovendo eficiência e qualidade | D23: # | E23: 0.15 | F23: 4 | G23: 8 | H23: 12
C24: Aumentar a contribuição para iniciativas técnicas ou projetos internos, agregando valor às entregas e ao funcionamento da equipa | D24: % | E24: 0.1 | F24: 0.8 | G24: 0.9 | H24: 1
C25: Desenvolver competências de liderança técnica ou operacional, apoiando colegas juniores e contribuindo para a organização das atividades. | D25: % | E25: 0.1 | F25: 0.8 | G25: 0.9 | H25: 1

Sheet Processo de Avaliação
B2: ETAPA COLABORADOR
B20: ETAPA LIDERANÇA
